<mujoco model="base">
  <compiler angle="radian" meshdir="meshes/" />
  <option impratio="20" cone="elliptic" />
  <size nconmax="5000" njmax="5000" />

  <asset>
  <texture builtin="gradient" height="256" rgb1=".9 .9 1." rgb2=".2 .3 .4" type="skybox" width="256" />
    <texture file="/Users/steve/miniconda3/envs/robosuite/lib/python3.8/site-packages/robosuite/models/assets/arenas/../textures/wood-tiles.png" type="2d" name="texplane" />
    <material name="floorplane" reflectance="0.01" shininess="0.0" specular="0.0" texrepeat="2 2" texture="texplane" texuniform="true" />
    
    <texture file="/Users/steve/miniconda3/envs/robosuite/lib/python3.8/site-packages/robosuite/models/assets/arenas/../textures/ceramic.png" type="cube" name="tex-ceramic" />
    <material name="table_ceramic" reflectance="0.0" shininess="0.0" specular="0.2" texrepeat="1 1" texture="tex-ceramic" />
    
    <texture file="/Users/steve/miniconda3/envs/robosuite/lib/python3.8/site-packages/robosuite/models/assets/arenas/../textures/steel-brushed.png" type="cube" name="tex-steel-brushed" />
    <material name="table_legs_metal" reflectance="0.8" shininess="0.8" texrepeat="1 1" texture="tex-steel-brushed" />
    
    <texture file="/Users/steve/miniconda3/envs/robosuite/lib/python3.8/site-packages/robosuite/models/assets/arenas/../textures/cream-plaster.png" type="2d" name="tex-cream-plaster" />
    <material name="walls_mat" reflectance="0.0" shininess="0.1" specular="0.1" texrepeat="3 3" texture="tex-cream-plaster" texuniform="true" />
    
    <texture name="textable" builtin="flat" height="512" width="512" rgb1="0.5 0.5 0.5" rgb2="0.5 0.5 0.5" />
    <material name="table_mat" texture="textable" />

  <mesh name="robot0_link0" file="/Users/steve/miniconda3/envs/robosuite/lib/python3.8/site-packages/robosuite/models/assets/robots/panda/meshes/link0.stl" />
        <mesh name="robot0_link1" file="/Users/steve/miniconda3/envs/robosuite/lib/python3.8/site-packages/robosuite/models/assets/robots/panda/meshes/link1.stl" />
        <mesh name="robot0_link2" file="/Users/steve/miniconda3/envs/robosuite/lib/python3.8/site-packages/robosuite/models/assets/robots/panda/meshes/link2.stl" />
        <mesh name="robot0_link3" file="/Users/steve/miniconda3/envs/robosuite/lib/python3.8/site-packages/robosuite/models/assets/robots/panda/meshes/link3.stl" />
        <mesh name="robot0_link4" file="/Users/steve/miniconda3/envs/robosuite/lib/python3.8/site-packages/robosuite/models/assets/robots/panda/meshes/link4.stl" />
        <mesh name="robot0_link5" file="/Users/steve/miniconda3/envs/robosuite/lib/python3.8/site-packages/robosuite/models/assets/robots/panda/meshes/link5.stl" />
        <mesh name="robot0_link6" file="/Users/steve/miniconda3/envs/robosuite/lib/python3.8/site-packages/robosuite/models/assets/robots/panda/meshes/link6.stl" />
        <mesh name="robot0_link7" file="/Users/steve/miniconda3/envs/robosuite/lib/python3.8/site-packages/robosuite/models/assets/robots/panda/meshes/link7.stl" />
        <mesh name="robot0_link0_vis" file="/Users/steve/miniconda3/envs/robosuite/lib/python3.8/site-packages/robosuite/models/assets/robots/panda/meshes/link0_vis.stl" />
        <mesh name="robot0_link1_vis" file="/Users/steve/miniconda3/envs/robosuite/lib/python3.8/site-packages/robosuite/models/assets/robots/panda/meshes/link1_vis.stl" />
        <mesh name="robot0_link2_vis" file="/Users/steve/miniconda3/envs/robosuite/lib/python3.8/site-packages/robosuite/models/assets/robots/panda/meshes/link2_vis.stl" />
        <mesh name="robot0_link3_vis" file="/Users/steve/miniconda3/envs/robosuite/lib/python3.8/site-packages/robosuite/models/assets/robots/panda/meshes/link3_vis.stl" />
        <mesh name="robot0_link4_vis" file="/Users/steve/miniconda3/envs/robosuite/lib/python3.8/site-packages/robosuite/models/assets/robots/panda/meshes/link4_vis.stl" />
        <mesh name="robot0_link5_vis" file="/Users/steve/miniconda3/envs/robosuite/lib/python3.8/site-packages/robosuite/models/assets/robots/panda/meshes/link5_vis.stl" />
        <mesh name="robot0_link6_vis" file="/Users/steve/miniconda3/envs/robosuite/lib/python3.8/site-packages/robosuite/models/assets/robots/panda/meshes/link6_vis.stl" />
        <mesh name="robot0_link7_vis" file="/Users/steve/miniconda3/envs/robosuite/lib/python3.8/site-packages/robosuite/models/assets/robots/panda/meshes/link7_vis.stl" />
        <mesh file="/Users/steve/miniconda3/envs/robosuite/lib/python3.8/site-packages/robosuite/models/assets/robots/panda/../common_meshes/pedestal.stl" name="robot0_pedestal" />

        
        <texture type="cube" name="robot0_pedestal_tex" builtin="flat" width="100" height="100" rgb1="0.2 0.2 0.2" rgb2="0.2 0.2 0.2" />
        <texture type="cube" name="robot0_torso_tex" builtin="flat" width="100" height="100" rgb1="0.2 0.2 0.2" rgb2="0.2 0.2 0.2" />
        <texture type="cube" name="robot0_arm_tex" builtin="flat" width="100" height="100" rgb1="1 1 1" rgb2="1 1 1" />

        
        <material name="robot0_pedestal_mat" texture="robot0_pedestal_tex" />
        <material name="robot0_torso_mat" texture="robot0_torso_tex" />
        <material name="robot0_arm_mat" texture="robot0_arm_tex" />
    <mesh name="gripper0_hand" file="/Users/steve/miniconda3/envs/robosuite/lib/python3.8/site-packages/robosuite/models/assets/grippers/meshes/panda_gripper/hand.stl" />
        <mesh name="gripper0_hand_vis" file="/Users/steve/miniconda3/envs/robosuite/lib/python3.8/site-packages/robosuite/models/assets/grippers/meshes/panda_gripper/hand_vis.stl" />
        <mesh name="gripper0_finger" file="/Users/steve/miniconda3/envs/robosuite/lib/python3.8/site-packages/robosuite/models/assets/grippers/meshes/panda_gripper/finger.stl" />
        <mesh name="gripper0_finger_vis" file="/Users/steve/miniconda3/envs/robosuite/lib/python3.8/site-packages/robosuite/models/assets/grippers/meshes/panda_gripper/finger_vis.stl" />
        <mesh name="gripper0_finger_vis2" file="/Users/steve/miniconda3/envs/robosuite/lib/python3.8/site-packages/robosuite/models/assets/grippers/meshes/panda_gripper/finger_longer.stl" />

        
        <texture type="cube" name="gripper0_hand_tex" builtin="flat" width="100" height="100" rgb1="1 1 1" rgb2="1 1 1" />
        <texture type="cube" name="gripper0_finger_tex" builtin="flat" width="100" height="100" rgb1="0.5 0.5 0.5" rgb2="0.5 0.5 0.5" />

        
        <material name="gripper0_hand_mat" texture="gripper0_hand_tex" />
        <material name="gripper0_finger_mat" texture="gripper0_finger_tex" />
    <texture type="cube" name="redwood" file="/Users/steve/miniconda3/envs/robosuite/lib/python3.8/site-packages/robosuite/models/assets/textures/red-wood.png" /><material texrepeat="1 1" specular="0.4" shininess="0.1" name="redwood_mat" texture="redwood" /></asset>

  <visual>
    <map znear="0.001" />
  </visual>

  <actuator>
  <motor ctrllimited="true" ctrlrange="-80.0 80.0" joint="robot0_joint1" name="robot0_torq_j1" />
        <motor ctrllimited="true" ctrlrange="-80.0 80.0" joint="robot0_joint2" name="robot0_torq_j2" />
        <motor ctrllimited="true" ctrlrange="-80.0 80.0" joint="robot0_joint3" name="robot0_torq_j3" />
        <motor ctrllimited="true" ctrlrange="-80.0 80.0" joint="robot0_joint4" name="robot0_torq_j4" />
        <motor ctrllimited="true" ctrlrange="-80.0 80.0" joint="robot0_joint5" name="robot0_torq_j5" />
        <motor ctrllimited="true" ctrlrange="-12.0 12.0" joint="robot0_joint6" name="robot0_torq_j6" />
        <motor ctrllimited="true" ctrlrange="-12.0 12.0" joint="robot0_joint7" name="robot0_torq_j7" />
    <position ctrllimited="true" ctrlrange="0.0 0.04" joint="gripper0_finger_joint1" kp="1000000" name="gripper0_gripper_finger_joint1" forcelimited="true" forcerange="-20 20" />
        <position ctrllimited="true" ctrlrange="-0.04 0.0" joint="gripper0_finger_joint2" kp="1000000" name="gripper0_gripper_finger_joint2" forcelimited="true" forcerange="-20 20" />
    </actuator>

  <worldbody>
  <geom condim="3" material="floorplane" name="floor" pos="0.0 0.0 0.0" size="3 3 .125" type="plane" />
    
    <geom pos="-1.25 2.25 1.5" quat="0.6532815 0.6532815 0.2705981 0.2705981" size="1.06 1.5 0.01" type="box" conaffinity="0" contype="0" group="1" name="wall_leftcorner_visual" material="walls_mat" />
    <geom pos="-1.25 -2.25 1.5" quat="0.6532815 0.6532815 -0.2705981 -0.2705981" size="1.06 1.5 0.01" type="box" conaffinity="0" contype="0" group="1" name="wall_rightcorner_visual" material="walls_mat" />
    <geom pos="1.25 3.0 1.5" quat="0.7071 0.7071 0 0" size="1.75 1.5 0.01" type="box" conaffinity="0" contype="0" group="1" name="wall_left_visual" material="walls_mat" />
    <geom pos="1.25 -3.0 1.5" quat="0.7071 -0.7071 0 0" size="1.75 1.5 0.01" type="box" conaffinity="0" contype="0" group="1" name="wall_right_visual" material="walls_mat" />
    <geom pos="-2.0 0.0 1.5" quat="0.5 0.5 0.5 0.5" size="1.5 1.5 0.01" type="box" conaffinity="0" contype="0" group="1" name="wall_rear_visual" material="walls_mat" />
    <geom pos="3.0 0.0 1.5" quat="0.5 0.5 -0.5 -0.5" size="3 1.5 0.01" type="box" conaffinity="0" contype="0" group="1" name="wall_front_visual" material="walls_mat" />
    
    <body name="table" pos="0.0 0.0 0.775">
      <geom pos="0 0 0" size="0.4 0.4 0.025" type="box" name="table_collision" friction="1.0 0.005 0.0001" />
      <geom pos="0 0 0" size="0.4 0.4 0.025" type="box" conaffinity="0" contype="0" group="1" name="table_visual" material="table_ceramic" />
      <site pos="0.0 0.0 0.025" name="table_top" size="0.001 0.001 0.001" rgba="0 0 0 0" />
      
      <geom pos="0.30000000000000004 0.30000000000000004 -0.3875" size="0.025 0.3875" type="cylinder" conaffinity="0" contype="0" group="1" name="table_leg1_visual" material="table_legs_metal" />
      <geom pos="-0.30000000000000004 0.30000000000000004 -0.3875" size="0.025 0.3875" type="cylinder" conaffinity="0" contype="0" group="1" name="table_leg2_visual" material="table_legs_metal" />
      <geom pos="-0.30000000000000004 -0.30000000000000004 -0.3875" size="0.025 0.3875" type="cylinder" conaffinity="0" contype="0" group="1" name="table_leg3_visual" material="table_legs_metal" />
      <geom pos="0.30000000000000004 -0.30000000000000004 -0.3875" size="0.025 0.3875" type="cylinder" conaffinity="0" contype="0" group="1" name="table_leg4_visual" material="table_legs_metal" />
    </body>

    <light name="light1" diffuse=".8 .8 .8" dir="0 -.15 -1" directional="false" pos="1.0 1.0 4.0" specular="0.3 0.3 0.3" castshadow="false" />
    <light name="light2" diffuse=".8 .8 .8" dir="0 -.15 -1" directional="false" pos="-3.0 -3.0 4.0" specular="0.3 0.3 0.3" castshadow="false" />
    
    <camera mode="fixed" name="frontview" pos="1.6 0.0 1.45" quat="0.56 0.43 0.43 0.56" />
    
    <camera mode="fixed" name="birdview" pos="-0.2 0.0 3.0" quat="0.7071 0 0 0.7071" />
    
    <camera mode="fixed" name="agentview" pos="0.5 0.0 1.35" quat="0.653 0.271 0.271 0.653" />
    
    <camera mode="fixed" name="sideview" pos="-0.05651774593317116 1.2761224129427358 1.4879572214102434" quat="0.009905065491771751 0.006877963156909582 0.5912228352893879 0.806418094001364" />
  <body name="robot0_link0" pos="-0.56 0.0 0.913">
            <body name="robot0_base" pos="0 0 0">

                
                <camera mode="fixed" name="robot0_robotview" pos="1.0 0 0.4" quat="0.653 0.271 0.271 0.653" />
                <inertial diaginertia="0 0 0" mass="0" pos="0 0 0" />
                <body name="robot0_controller_box" pos="0 0 0">
                    <inertial diaginertia="1.71363 1.27988 0.809981" mass="46.64" pos="-0.325 0 -0.38" />
                    <geom pos="-0.325 0 -0.38" size="0.11 0.2 0.265" type="box" name="robot0_controller_box_col" />
                </body>
                <body name="robot0_pedestal_feet" pos="0 0 0">
                    <inertial diaginertia="8.16095 9.59375 15.0785" mass="167.09" pos="-0.1225 0 -0.758" />
                    <geom pos="-0.1225 0 -0.758" size="0.385 0.35 0.155" type="box" name="robot0_pedestal_feet_col" />
                </body>
                <body name="robot0_torso" pos="0 0 0">
                    <inertial diaginertia="1e-08 1e-08 1e-08" mass="0.0001" pos="0 0 0" />
                    <geom conaffinity="0" contype="0" group="1" pos="0 0 -0.05" size="0.05 0.05 0.05" type="box" name="robot0_torso_col" material="robot0_torso_mat" />
                </body>
                <body name="robot0_pedestal" pos="0 0 0">
                    <inertial diaginertia="6.0869 5.81635 4.20915" mass="60.864" pos="0 0 0" quat="0.659267 -0.259505 -0.260945 0.655692" />
                    <geom conaffinity="0" contype="0" group="1" mesh="robot0_pedestal" type="mesh" name="robot0_pedestal_col1" material="robot0_pedestal_mat" />
                    <geom pos="-0.02 0 -0.29" rgba="0.2 0.2 0.2 1" size="0.18 0.31" type="cylinder" name="robot0_pedestal_col2" />
                </body>
            </body>
            <inertial pos="0 0 0.05" mass="4" diaginertia="0.4 0.4 0.4" />
            <geom type="mesh" contype="0" conaffinity="0" group="1" mesh="robot0_link0_vis" name="robot0_link0_visual" material="robot0_arm_mat" />
            <geom type="mesh" group="0" mesh="robot0_link0" name="robot0_link0_collision" />
            <body name="robot0_link1" pos="0 0 0.333">
                <inertial pos="0 0 -0.07" mass="3" diaginertia="0.3 0.3 0.3" />
                <joint name="robot0_joint1" pos="0 0 0" axis="0 0 1" limited="true" range="-2.8973 2.8973" damping="0.1" />
                <geom type="mesh" contype="0" conaffinity="0" group="1" mesh="robot0_link1_vis" name="robot0_link1_visual" material="robot0_arm_mat" />
                <geom type="mesh" group="0" mesh="robot0_link1" name="robot0_link1_collision" />
                <body name="robot0_link2" pos="0 0 0" quat="0.707107 -0.707107 0 0">
                    <inertial pos="0 -0.1 0" mass="3" diaginertia="0.3 0.3 0.3" />
                    <joint name="robot0_joint2" pos="0 0 0" axis="0 0 1" limited="true" range="-1.7628 1.7628" damping="0.1" />
                    <geom type="mesh" contype="0" conaffinity="0" group="1" mesh="robot0_link2_vis" name="robot0_link2_visual" material="robot0_arm_mat" />
                    <geom type="mesh" group="0" mesh="robot0_link2" name="robot0_link2_collision" />
                    <body name="robot0_link3" pos="0 -0.316 0" quat="0.707107 0.707107 0 0">
                        <inertial pos="0.04 0 -0.05" mass="2" diaginertia="0.2 0.2 0.2" />
                        <joint name="robot0_joint3" pos="0 0 0" axis="0 0 1" limited="true" range="-2.8973 2.8973" damping="0.1" />
                        <geom type="mesh" contype="0" conaffinity="0" group="1" mesh="robot0_link3_vis" name="robot0_link3_visual" material="robot0_arm_mat" />
                        <geom type="mesh" group="0" mesh="robot0_link3" name="robot0_link3_collision" />
                        <body name="robot0_link4" pos="0.0825 0 0" quat="0.707107 0.707107 0 0">
                            <inertial pos="-0.04 0.05 0" mass="2" diaginertia="0.2 0.2 0.2" />
                            <joint name="robot0_joint4" pos="0 0 0" axis="0 0 1" limited="true" range="-3.0718 -0.0698" damping="0.1" />
                            <geom type="mesh" contype="0" conaffinity="0" group="1" mesh="robot0_link4_vis" name="robot0_link4_visual" material="robot0_arm_mat" />
                            <geom type="mesh" group="0" mesh="robot0_link4" name="robot0_link4_collision" />
                            <body name="robot0_link5" pos="-0.0825 0.384 0" quat="0.707107 -0.707107 0 0">
                                <inertial pos="0 0 -0.15" mass="2" diaginertia="0.2 0.2 0.2" />
                                <joint name="robot0_joint5" pos="0 0 0" axis="0 0 1" limited="true" range="-2.8973 2.8973" damping="0.1" />
                                <geom type="mesh" contype="0" conaffinity="0" group="1" mesh="robot0_link5_vis" name="robot0_link5_visual" material="robot0_arm_mat" />
                                <geom type="mesh" group="0" mesh="robot0_link5" name="robot0_link5_collision" />
                                <body name="robot0_link6" pos="0 0 0" quat="0.707107 0.707107 0 0">
                                    <inertial pos="0.06 0 0" mass="1.5" diaginertia="0.1 0.1 0.1" />
                                    <joint name="robot0_joint6" pos="0 0 0" axis="0 0 1" limited="true" range="-0.0175 3.7525" damping="0.01" />
                                    <geom type="mesh" contype="0" conaffinity="0" group="1" mesh="robot0_link6_vis" name="robot0_link6_visual" material="robot0_arm_mat" />
                                    <geom type="mesh" group="0" mesh="robot0_link6" name="robot0_link6_collision" />
                                    <body name="robot0_link7" pos="0.088 0 0" quat="0.707107 0.707107 0 0">
                                        <inertial pos="0 0 0.08" mass="0.5" diaginertia="0.05 0.05 0.05" />
                                        <joint name="robot0_joint7" pos="0 0 0" axis="0 0 1" limited="true" range="-2.8973 2.8973" damping="0.01" />
                                        <geom type="mesh" contype="0" conaffinity="0" group="1" mesh="robot0_link7_vis" name="robot0_link7_visual" material="robot0_arm_mat" />
                                        <geom type="mesh" group="0" mesh="robot0_link7" name="robot0_link7_collision" />
                                        
                                        <body name="robot0_right_hand" pos="0 0 0.1065" quat="0.924 0 0 -0.383">
                                            <inertial pos="0 0 0" mass="0.5" diaginertia="0.05 0.05 0.05" />
                                            
                                            
                                            
                                            <site name="robot0_ee" pos="0 0 0" size="0.01 0.01 0.01" rgba="0 0 1 1" type="sphere" group="1" />
                                            <site name="robot0_ee_x" pos="0 0 0" size="0.005 .1" quat="0.707105 0.707108 0 0 " rgba="1 0 0 0" type="cylinder" group="1" />
                                            <site name="robot0_ee_z" pos="0 0 0" size="0.005 .1" quat="0.707105 0 0 0.707108" rgba="0 0 1 0" type="cylinder" group="1" />
                                            <site name="robot0_ee_y" pos="0 0 0" size="0.005 .1" quat="0.707105 0 0.707108 0 " rgba="0 1 0 0" type="cylinder" group="1" />
                                            
                                            <camera mode="fixed" name="robot0_eye_in_hand" pos="0.05 0 0" quat="0 0.707108 0.707108 0" fovy="75" />
                                            
                                        <body name="gripper0_right_gripper" pos="0 0 0" quat="0.707107 0 0 -0.707107">
            <site name="gripper0_ft_frame" pos="0 0 0" size="0.01 0.01 0.01" rgba="1 0 0 1" type="sphere" group="1" />
            <inertial pos="0 0 0.17" quat="0.707107 0.707107 0 0" mass="0.3" diaginertia="0.09 0.07 0.05" />
            <geom pos="0 0 0." quat="0.707107 0 0 0.707107" type="mesh" contype="0" conaffinity="0" group="1" mesh="gripper0_hand_vis" name="gripper0_hand_visual" material="gripper0_hand_mat" />
            <geom pos="0 0 0." quat="0.707107 0 0 0.707107" type="mesh" mesh="gripper0_hand" group="0" name="gripper0_hand_collision" />
            
            <site name="gripper0_grip_site" pos="0 0 0.097" size="0.01 0.01 0.01" rgba="1 0 0 1" type="sphere" group="1" />
            
            <site name="gripper0_grip_site_cylinder" pos="0 0 0.1399" size="0.005 10" rgba="0 1 0 0.3" type="cylinder" group="1" />
            <body name="gripper0_leftfinger" pos="0 0 0.0524" quat="0.707107 0 0 0.707107">
                <inertial pos="0 0 0.05" mass="0.1" diaginertia="0.01 0.01 0.005" />
                <joint name="gripper0_finger_joint1" pos="0 0 0" axis="0 1 0" type="slide" limited="true" range="0.0 0.04" damping="100" />
                <geom type="mesh" contype="0" conaffinity="0" group="1" mesh="gripper0_finger_vis" name="gripper0_finger1_visual" material="gripper0_finger_mat" />
                <geom type="mesh" conaffinity="1" contype="0" solref="0.02 1" friction="1 0.005 0.0001" condim="4" mesh="gripper0_finger" name="gripper0_finger1_collision" />
                <body name="gripper0_finger_joint1_tip" pos="0 0.0085 0.056">
                    <inertial pos="0 0 0" quat="0 0 0 1" mass="0.01" diaginertia="0.01 0.01 0.01" />
                    <geom size="0.008 0.004 0.008" pos="0 -0.005 -0.015" quat="0 0 0 1" type="box" solref="0.01 0.5" friction="2 0.05 0.0001" conaffinity="1" contype="1" name="gripper0_finger1_tip_collision" />
                </body>
            </body>
            <body name="gripper0_rightfinger" pos="0 0 0.0524" quat="0.707107 0 0 0.707107">
                <inertial pos="0 0 0.05" mass="0.1" diaginertia="0.01 0.01 0.005" />
                <joint name="gripper0_finger_joint2" pos="0 0 0" axis="0 1 0" type="slide" limited="true" range="-0.04 0.0" damping="100" />
                <geom quat="0 0 0 1" type="mesh" contype="0" conaffinity="0" group="1" mesh="gripper0_finger_vis" name="gripper0_finger2_visual" material="gripper0_finger_mat" />
                <geom quat="0 0 0 1" type="mesh" conaffinity="1" contype="0" solref="0.02 1" friction="1 0.005 0.0001" condim="4" mesh="gripper0_finger" name="gripper0_finger2_collision" />
                <body name="gripper0_finger_joint2_tip" pos="0 -0.0085 0.056">
                    <inertial pos="0 0 0" quat="0 0 0 1" mass="0.01" diaginertia="0.01 0.01 0.01" />
                    <geom size="0.008 0.004 0.008" pos="0 0.005 -0.015" quat="0 0 0 1" type="box" solref="0.01 0.5" friction="2 0.05 0.0001" conaffinity="1" contype="1" name="gripper0_finger2_tip_collision" />
                </body>
            </body>
        </body>
    </body>
                                    </body>
                                </body>
                            </body>
                        </body>
                    </body>
                </body>
            </body>
        </body>
    <body name="cube" pos="-0.01899890260184152 -0.014690558172663683 0.831403749283911" quat="0.7901024991050422 0.0 0.0 0.6129747473656374"><geom pos="0 0 0" group="1" name="cube" type="box" material="redwood_mat" size="0.02103403758459453 0.021712345983311603 0.021403749283911033" density="1000" friction="1 0.005 0.0001" solref="0.02 1.0" solimp="0.9 0.95 0.001" /><site pos="0 0 0" size="0.002 0.002 0.002" rgba="1 0 0 1" type="sphere" name="cube" /><joint name="cube_jnt0" type="free" /></body></worldbody>

  <equality>
  </equality>
<sensor><force name="gripper0_force_ee" site="gripper0_ft_frame" />
        <torque name="gripper0_torque_ee" site="gripper0_ft_frame" />
    </sensor><tendon /><contact /><default /></mujoco>